Workbook

Sheet README
B1: LAB20: si plotesohet NetBox-i me import (2 core, 2 agg, 10 access)
B2: Cdo flete eshte NJE faqe Import ne NetBox. Importohen me radhe, sepse cdo objekt i referohet objekteve te krijuara me pare (pajisja i duhet site-i, kablli i duhen portat...).
B3: Si importohet nje flete: selekto te gjitha qelizat me te dhena (Ctrl+A ne flete), Ctrl+C, ne NetBox hap faqen e Import-it, ngjit te kutia 'Data', Submit. Rreshti 1 (emrat e kolonave) duhet te jete gjithmone brenda.
B4: Kerkohet qe ne NetBox te ekzistojne tashme: manufacturer HPE, device types Aruba 8360 dhe 6300M, rolet Core/Agg/Access, platforma 'Aruba AOS-CX' me config template 'Aruba CX', VRF-te 'mgmt' dhe 'KA'. Te gjitha krijohen nga 'python -m nblab setup-gui' + Build site LAB01.
A6: # | B6: Fleta | C6: Ku ne NetBox | D6: Cfare krijon / shenime
A7: 1 | B7: 01_site | C7: Organization > Sites > Import | D7: Site-i LAB20.
A8: 2 | B8: 02_locations | C8: Organization > Locations > Import | D8: MDF, Floor 1, Floor 2 (dhomat/katet).
A9: 3 | B9: 03_vlan_group | C9: IPAM > VLAN Groups > Import | D9: Grupi i VLAN-eve, i lidhur me site-in (scope). Pa kete, VLAN-et nuk dalin ne config.
A10: 4 | B10: 04_vlans | C10: IPAM > VLANs > Import | D10: 5 VLAN: 10 Users, 20 Voice, 30 WiFi, 99 Mgmt, 999 Parking.
A11: 5 | B11: 05_prefixes | C11: IPAM > Prefixes > Import | D11: Subnet-et 10.20.x.0/24, secili i lidhur me VLAN-in; rangjet infra (p2p, keepalive, OOB, loopback).
A12: 6 | B12: 06_devices | C12: Devices > Devices > Import | D12: 14 switch-a. NetBox krijon VETE portat 1/1/1...1/1/54 + mgmt nga modeli (device type).
A13: 7 | B13: 07_interfaces_new | C13: Devices > Interfaces > Import | D13: Interface-at qe NUK vijne nga modeli: LAG-et (lag1, lag256), SVI-te (vlan10...), loopback0.
A14: 8 | B14: 08_ports_update | C14: Devices > Interfaces > Import | D14: Portat ekzistuese (te krijuara ne hapin 6) perditesohen: LAG-u, VLAN-et, VRF, MTU, pershkrimi. Kerkon kolonen 'id': shiko hapin 8a.
A15: 8a | B15: _ids | C15: Devices > Interfaces | D15: Filtro Site = LAB20 > Configure Table: vetem ID, Device, Name (me kete radhe) > Export > Current view. Ngjit kolonat ne _ids!A:C. Kolona 'id' te 08 mbushet vete (nese del MISSING, mungon ai port ne export).
A16: 9 | B16: 09_cables | C16: Devices > Cables > Import | D16: 30 kabllo: ISL, keepalive, core-agg, access uplinks.
A17: 10 | B17: 10_ip_addresses | C17: IPAM > IP Addresses > Import | D17: IP-te. role=vip eshte gateway-i (VSX active-gateway), i njejti ne te dy AGG. is_primary=true = IP e menaxhimit te pajisjes.
A18: 11 | B18: 11_context_GUI | C18: Me dore ne GUI (pa import) | D18: Standardet (NTP, DNS, TACACS...) dhe VSX per 4 pajisjet: kopjo JSON-in nga kjo flete.
A19: 12 | B19: - | C19: Customization > Scripts > Validate site | D19: Zgjidh LAB20. Duhet: 0 errors.
A20: 13 | B20: - | C20: Device > Render Config | D20: Config-i Aruba CX i cdo switch-i.
B22: Si ta perdoresh per nje site tjeter: zevendeso LAB20 / 10.20 me site-in e ri ne te gjitha fletet (Ctrl+H), ndrysho pajisjet ne 06 dhe lidhjet ne 08/09. Rregulli: cdo port qe permendet ne 08, 09 ose 10 duhet te ekzistoje (nga modeli ose nga 07).
B23: Kujdes: te interface-at kolona quhet 'vrf.name', sepse NetBox-i e kerkon VRF-ne e interface-it me RD; me '.name' i thua ta kerkoje me emer. E njejta sintakse (fusha.atributi) vlen per cdo kolone.
B24: Legjenda: rreshti 1 i cdo flete = emrat e fushave te NetBox-it, mos i ndrysho. Kolonat bosh lejohen. Ne 08 kolona 'id' eshte formule: mos e shkruaj me dore.

Sheet 01_site
A1: name | B1: slug | C1: status | D1: description
A2: LAB20 | B2: lab20 | C2: active | D2: Test campus: 2 core, 2 agg, 10 access

Sheet 02_locations
A1: site | B1: name | C1: slug | D1: status
A2: LAB20 | B2: MDF | C2: lab20-mdf | D2: active
A3: LAB20 | B3: Floor 1 | C3: lab20-f1 | D3: active
A4: LAB20 | B4: Floor 2 | C4: lab20-f2 | D4: active

Sheet 03_vlan_group
A1: name | B1: slug | C1: scope_type | D1: scope_name
A2: LAB20 VLANs | B2: lab20-vlans | C2: dcim.site | D2: LAB20

Sheet 04_vlans
A1: group | B1: vid | C1: name | D1: status | E1: description
A2: LAB20 VLANs | B2: 10 | C2: Users | D2: active
A3: LAB20 VLANs | B3: 20 | C3: Voice | D3: active
A4: LAB20 VLANs | B4: 30 | C4: WiFi | D4: active
A5: LAB20 VLANs | B5: 99 | C5: Mgmt | D5: active
A6: LAB20 VLANs | B6: 999 | C6: Parking | D6: active | E6: Unused ports, no gateway

Sheet 05_prefixes
A1: prefix | B1: vrf | C1: vlan_group | D1: vlan | E1: status | F1: scope_type | G1: scope_name | H1: description
A2: 10.20.10.0/24 | C2: LAB20 VLANs | D2: 10 | E2: active | F2: dcim.site | G2: LAB20 | H2: Users
A3: 10.20.20.0/24 | C3: LAB20 VLANs | D3: 20 | E3: active | F3: dcim.site | G3: LAB20 | H3: Voice
A4: 10.20.30.0/24 | C4: LAB20 VLANs | D4: 30 | E4: active | F4: dcim.site | G4: LAB20 | H4: WiFi
A5: 10.20.99.0/24 | C5: LAB20 VLANs | D5: 99 | E5: active | F5: dcim.site | G5: LAB20 | H5: Mgmt
A6: 10.20.251.0/24 | E6: container | F6: dcim.site | G6: LAB20 | H6: Core-agg links (/31)
A7: 10.20.252.0/24 | B7: KA | E7: container | F7: dcim.site | G7: LAB20 | H7: VSX keepalive (/31)
A8: 10.20.253.0/24 | B8: mgmt | E8: active | F8: dcim.site | G8: LAB20 | H8: Out-of-band management
A9: 10.20.254.0/24 | E9: container | F9: dcim.site | G9: LAB20 | H9: Loopbacks (/32)

Sheet 06_devices
A1: name | B1: role | C1: manufacturer | D1: device_type | E1: platform | F1: site | G1: location | H1: status
A2: LAB20-CORE-01 | B2: Core | C2: HPE | D2: Aruba 8360-48Y6C Front-to-Back | E2: Aruba AOS-CX | F2: LAB20 | G2: MDF | H2: active
A3: LAB20-CORE-02 | B3: Core | C3: HPE | D3: Aruba 8360-48Y6C Front-to-Back | E3: Aruba AOS-CX | F3: LAB20 | G3: MDF | H3: active
A4: LAB20-AGG-01 | B4: Agg | C4: HPE | D4: Aruba 8360-48Y6C Front-to-Back | E4: Aruba AOS-CX | F4: LAB20 | G4: MDF | H4: active
A5: LAB20-AGG-02 | B5: Agg | C5: HPE | D5: Aruba 8360-48Y6C Front-to-Back | E5: Aruba AOS-CX | F5: LAB20 | G5: MDF | H5: active
A6: LAB20-F1-ACC-01 | B6: Access | C6: HPE | D6: Aruba 6300M-48G-POE4-4SFP56 | E6: Aruba AOS-CX | F6: LAB20 | G6: Floor 1 | H6: active
A7: LAB20-F1-ACC-02 | B7: Access | C7: HPE | D7: Aruba 6300M-48G-POE4-4SFP56 | E7: Aruba AOS-CX | F7: LAB20 | G7: Floor 1 | H7: active
A8: LAB20-F1-ACC-03 | B8: Access | C8: HPE | D8: Aruba 6300M-48G-POE4-4SFP56 | E8: Aruba AOS-CX | F8: LAB20 | G8: Floor 1 | H8: active
A9: LAB20-F1-ACC-04 | B9: Access | C9: HPE | D9: Aruba 6300M-48G-POE4-4SFP56 | E9: Aruba AOS-CX | F9: LAB20 | G9: Floor 1 | H9: active
A10: LAB20-F1-ACC-05 | B10: Access | C10: HPE | D10: Aruba 6300M-48G-POE4-4SFP56 | E10: Aruba AOS-CX | F10: LAB20 | G10: Floor 1 | H10: active
A11: LAB20-F2-ACC-01 | B11: Access | C11: HPE | D11: Aruba 6300M-48G-POE4-4SFP56 | E11: Aruba AOS-CX | F11: LAB20 | G11: Floor 2 | H11: active
A12: LAB20-F2-ACC-02 | B12: Access | C12: HPE | D12: Aruba 6300M-48G-POE4-4SFP56 | E12: Aruba AOS-CX | F12: LAB20 | G12: Floor 2 | H12: active
... A15: LAB20-F2-ACC-05 | B15: Access | C15: HPE | D15: Aruba 6300M-48G-POE4-4SFP56 | E15: Aruba AOS-CX | F15: LAB20 | G15: Floor 2 | H15: active

Sheet 07_interfaces_new
A1: device | B1: name | C1: type | D1: mode | E1: vlan_group | F1: tagged_vlans | G1: mtu | H1: vrf.name | I1: description
A2: LAB20-CORE-01 | B2: lag256 | C2: lag | D2: tagged-all | G2: 9198 | I2: VSX ISL
A3: LAB20-CORE-01 | B3: loopback0 | C3: virtual | I3: Router ID
A4: LAB20-CORE-02 | B4: lag256 | C4: lag | D4: tagged-all | G4: 9198 | I4: VSX ISL
A5: LAB20-CORE-02 | B5: loopback0 | C5: virtual | I5: Router ID
A6: LAB20-AGG-01 | B6: lag256 | C6: lag | D6: tagged-all | G6: 9198 | I6: VSX ISL
A7: LAB20-AGG-01 | B7: loopback0 | C7: virtual | I7: Router ID
A8: LAB20-AGG-02 | B8: lag256 | C8: lag | D8: tagged-all | G8: 9198 | I8: VSX ISL
A9: LAB20-AGG-02 | B9: loopback0 | C9: virtual | I9: Router ID
A10: LAB20-AGG-01 | B10: lag1 | C10: lag | D10: tagged | E10: LAB20 VLANs | F10: 10,20,30,99 | G10: 9198 | I10: MC-LAG to LAB20-F1-ACC-01
A11: LAB20-AGG-02 | B11: lag1 | C11: lag | D11: tagged | E11: LAB20 VLANs | F11: 10,20,30,99 | G11: 9198 | I11: MC-LAG to LAB20-F1-ACC-01
A12: LAB20-AGG-01 | B12: lag2 | C12: lag | D12: tagged | E12: LAB20 VLANs | F12: 10,20,30,99 | G12: 9198 | I12: MC-LAG to LAB20-F1-ACC-02
A13: LAB20-AGG-02 | B13: lag2 | C13: lag | D13: tagged | E13: LAB20 VLANs | F13: 10,20,30,99 | G13: 9198 | I13: MC-LAG to LAB20-F1-ACC-02
A14: LAB20-AGG-01 | B14: lag3 | C14: lag | D14: tagged | E14: LAB20 VLANs | F14: 10,20,30,99 | G14: 9198 | I14: MC-LAG to LAB20-F1-ACC-03
A15: LAB20-AGG-02 | B15: lag3 | C15: lag | D15: tagged | E15: LAB20 VLANs | F15: 10,20,30,99 | G15: 9198 | I15: MC-LAG to LAB20-F1-ACC-03
A16: LAB20-AGG-01 | B16: lag4 | C16: lag | D16: tagged | E16: LAB20 VLANs | F16: 10,20,30,99 | G16: 9198 | I16: MC-LAG to LAB20-F1-ACC-04
A17: LAB20-AGG-02 | B17: lag4 | C17: lag | D17: tagged | E17: LAB20 VLANs | F17: 10,20,30,99 | G17: 9198 | I17: MC-LAG to LAB20-F1-ACC-04
A18: LAB20-AGG-01 | B18: lag5 | C18: lag | D18: tagged | E18: LAB20 VLANs | F18: 10,20,30,99 | G18: 9198 | I18: MC-LAG to LAB20-F1-ACC-05
A19: LAB20-AGG-02 | B19: lag5 | C19: lag | D19: tagged | E19: LAB20 VLANs | F19: 10,20,30,99 | G19: 9198 | I19: MC-LAG to LAB20-F1-ACC-05
A20: LAB20-AGG-01 | B20: lag6 | C20: lag | D20: tagged | E20: LAB20 VLANs | F20: 10,20,30,99 | G20: 9198 | I20: MC-LAG to LAB20-F2-ACC-01
A21: LAB20-AGG-02 | B21: lag6 | C21: lag | D21: tagged | E21: LAB20 VLANs | F21: 10,20,30,99 | G21: 9198 | I21: MC-LAG to LAB20-F2-ACC-01
... A29: LAB20-AGG-02 | B29: lag10 | C29: lag | D29: tagged | E29: LAB20 VLANs | F29: 10,20,30,99 | G29: 9198 | I29: MC-LAG to LAB20-F2-ACC-05
A30: LAB20-AGG-01 | B30: vlan10 | C30: virtual | I30: Users
A31: LAB20-AGG-01 | B31: vlan20 | C31: virtual | I31: Voice
A32: LAB20-AGG-01 | B32: vlan30 | C32: virtual | I32: WiFi
A33: LAB20-AGG-01 | B33: vlan99 | C33: virtual | I33: Mgmt
A34: LAB20-AGG-02 | B34: vlan10 | C34: virtual | I34: Users
A35: LAB20-AGG-02 | B35: vlan20 | C35: virtual | I35: Voice
A36: LAB20-AGG-02 | B36: vlan30 | C36: virtual | I36: WiFi
A37: LAB20-AGG-02 | B37: vlan99 | C37: virtual | I37: Mgmt
A38: LAB20-F1-ACC-01 | B38: lag1 | C38: lag | D38: tagged | E38: LAB20 VLANs | F38: 10,20,30,99 | G38: 9198 | I38: Uplink to AGG VSX
A39: LAB20-F1-ACC-01 | B39: vlan99 | C39: virtual | I39: Management
A40: LAB20-F1-ACC-02 | B40: lag1 | C40: lag | D40: tagged | E40: LAB20 VLANs | F40: 10,20,30,99 | G40: 9198 | I40: Uplink to AGG VSX
A41: LAB20-F1-ACC-02 | B41: vlan99 | C41: virtual | I41: Management
A42: LAB20-F1-ACC-03 | B42: lag1 | C42: lag | D42: tagged | E42: LAB20 VLANs | F42: 10,20,30,99 | G42: 9198 | I42: Uplink to AGG VSX
A43: LAB20-F1-ACC-03 | B43: vlan99 | C43: virtual | I43: Management
A44: LAB20-F1-ACC-04 | B44: lag1 | C44: lag | D44: tagged | E44: LAB20 VLANs | F44: 10,20,30,99 | G44: 9198 | I44: Uplink to AGG VSX
A45: LAB20-F1-ACC-04 | B45: vlan99 | C45: virtual | I45: Management
A46: LAB20-F1-ACC-05 | B46: lag1 | C46: lag | D46: tagged | E46: LAB20 VLANs | F46: 10,20,30,99 | G46: 9198 | I46: Uplink to AGG VSX
A47: LAB20-F1-ACC-05 | B47: vlan99 | C47: virtual | I47: Management
...

Sheet 08_ports_update
A1: id | B1: device | C1: name | D1: lag | E1: mode | F1: vlan_group | G1: untagged_vlan | H1: tagged_vlans | I1: mtu | J1: vrf.name | K1: enabled | L1: description
A2: =IFERROR(INDEX(_ids!$A:$A,MATCH(B2&"|"&C2,_ids!$D:$D,0)),"MISSING") -> MISSING | B2: LAB20-CORE-01 | C2: mgmt | J2: mgmt | K2: true | L2: OOB management
A3: =IFERROR(INDEX(_ids!$A:$A,MATCH(B3&"|"&C3,_ids!$D:$D,0)),"MISSING") -> MISSING | B3: LAB20-CORE-01 | C3: 1/1/48 | J3: KA | K3: true | L3: VSX keepalive
A4: =IFERROR(INDEX(_ids!$A:$A,MATCH(B4&"|"&C4,_ids!$D:$D,0)),"MISSING") -> MISSING | B4: LAB20-CORE-01 | C4: 1/1/53 | D4: lag256 | K4: true | L4: VSX ISL member
A5: =IFERROR(INDEX(_ids!$A:$A,MATCH(B5&"|"&C5,_ids!$D:$D,0)),"MISSING") -> MISSING | B5: LAB20-CORE-01 | C5: 1/1/54 | D5: lag256 | K5: true | L5: VSX ISL member
A6: =IFERROR(INDEX(_ids!$A:$A,MATCH(B6&"|"&C6,_ids!$D:$D,0)),"MISSING") -> MISSING | B6: LAB20-CORE-02 | C6: mgmt | J6: mgmt | K6: true | L6: OOB management
A7: =IFERROR(INDEX(_ids!$A:$A,MATCH(B7&"|"&C7,_ids!$D:$D,0)),"MISSING") -> MISSING | B7: LAB20-CORE-02 | C7: 1/1/48 | J7: KA | K7: true | L7: VSX keepalive
A8: =IFERROR(INDEX(_ids!$A:$A,MATCH(B8&"|"&C8,_ids!$D:$D,0)),"MISSING") -> MISSING | B8: LAB20-CORE-02 | C8: 1/1/53 | D8: lag256 | K8: true | L8: VSX ISL member
A9: =IFERROR(INDEX(_ids!$A:$A,MATCH(B9&"|"&C9,_ids!$D:$D,0)),"MISSING") -> MISSING | B9: LAB20-CORE-02 | C9: 1/1/54 | D9: lag256 | K9: true | L9: VSX ISL member
A10: =IFERROR(INDEX(_ids!$A:$A,MATCH(B10&"|"&C10,_ids!$D:$D,0)),"MISSING") -> MISSING | B10: LAB20-AGG-01 | C10: mgmt | J10: mgmt | K10: true | L10: OOB management
A11: =IFERROR(INDEX(_ids!$A:$A,MATCH(B11&"|"&C11,_ids!$D:$D,0)),"MISSING") -> MISSING | B11: LAB20-AGG-01 | C11: 1/1/48 | J11: KA | K11: true | L11: VSX keepalive
A12: =IFERROR(INDEX(_ids!$A:$A,MATCH(B12&"|"&C12,_ids!$D:$D,0)),"MISSING") -> MISSING | B12: LAB20-AGG-01 | C12: 1/1/53 | D12: lag256 | K12: true | L12: VSX ISL member
A13: =IFERROR(INDEX(_ids!$A:$A,MATCH(B13&"|"&C13,_ids!$D:$D,0)),"MISSING") -> MISSING | B13: LAB20-AGG-01 | C13: 1/1/54 | D13: lag256 | K13: true | L13: VSX ISL member
A14: =IFERROR(INDEX(_ids!$A:$A,MATCH(B14&"|"&C14,_ids!$D:$D,0)),"MISSING") -> MISSING | B14: LAB20-AGG-02 | C14: mgmt | J14: mgmt | K14: true | L14: OOB management
A15: =IFERROR(INDEX(_ids!$A:$A,MATCH(B15&"|"&C15,_ids!$D:$D,0)),"MISSING") -> MISSING | B15: LAB20-AGG-02 | C15: 1/1/48 | J15: KA | K15: true | L15: VSX keepalive
A16: =IFERROR(INDEX(_ids!$A:$A,MATCH(B16&"|"&C16,_ids!$D:$D,0)),"MISSING") -> MISSING | B16: LAB20-AGG-02 | C16: 1/1/53 | D16: lag256 | K16: true | L16: VSX ISL member
A17: =IFERROR(INDEX(_ids!$A:$A,MATCH(B17&"|"&C17,_ids!$D:$D,0)),"MISSING") -> MISSING | B17: LAB20-AGG-02 | C17: 1/1/54 | D17: lag256 | K17: true | L17: VSX ISL member
A18: =IFERROR(INDEX(_ids!$A:$A,MATCH(B18&"|"&C18,_ids!$D:$D,0)),"MISSING") -> MISSING | B18: LAB20-CORE-01 | C18: 1/1/49 | I18: 9198 | K18: true | L18: P2P to LAB20-AGG-01
A19: =IFERROR(INDEX(_ids!$A:$A,MATCH(B19&"|"&C19,_ids!$D:$D,0)),"MISSING") -> MISSING | B19: LAB20-AGG-01 | C19: 1/1/49 | I19: 9198 | K19: true | L19: P2P to LAB20-CORE-01
A20: =IFERROR(INDEX(_ids!$A:$A,MATCH(B20&"|"&C20,_ids!$D:$D,0)),"MISSING") -> MISSING | B20: LAB20-CORE-01 | C20: 1/1/50 | I20: 9198 | K20: true | L20: P2P to LAB20-AGG-02
A21: =IFERROR(INDEX(_ids!$A:$A,MATCH(B21&"|"&C21,_ids!$D:$D,0)),"MISSING") -> MISSING | B21: LAB20-AGG-02 | C21: 1/1/49 | I21: 9198 | K21: true | L21: P2P to LAB20-CORE-01
A22: =IFERROR(INDEX(_ids!$A:$A,MATCH(B22&"|"&C22,_ids!$D:$D,0)),"MISSING") -> MISSING | B22: LAB20-CORE-02 | C22: 1/1/49 | I22: 9198 | K22: true | L22: P2P to LAB20-AGG-01
A23: =IFERROR(INDEX(_ids!$A:$A,MATCH(B23&"|"&C23,_ids!$D:$D,0)),"MISSING") -> MISSING | B23: LAB20-AGG-01 | C23: 1/1/50 | I23: 9198 | K23: true | L23: P2P to LAB20-CORE-02
A24: =IFERROR(INDEX(_ids!$A:$A,MATCH(B24&"|"&C24,_ids!$D:$D,0)),"MISSING") -> MISSING | B24: LAB20-CORE-02 | C24: 1/1/50 | I24: 9198 | K24: true | L24: P2P to LAB20-AGG-02
A25: =IFERROR(INDEX(_ids!$A:$A,MATCH(B25&"|"&C25,_ids!$D:$D,0)),"MISSING") -> MISSING | B25: LAB20-AGG-02 | C25: 1/1/50 | I25: 9198 | K25: true | L25: P2P to LAB20-CORE-02
A26: =IFERROR(INDEX(_ids!$A:$A,MATCH(B26&"|"&C26,_ids!$D:$D,0)),"MISSING") -> MISSING | B26: LAB20-AGG-01 | C26: 1/1/1 | D26: lag1 | K26: true | L26: To LAB20-F1-ACC-01 1/1/49
A27: =IFERROR(INDEX(_ids!$A:$A,MATCH(B27&"|"&C27,_ids!$D:$D,0)),"MISSING") -> MISSING | B27: LAB20-F1-ACC-01 | C27: 1/1/49 | D27: lag1 | K27: true | L27: To LAB20-AGG-01 1/1/1
A28: =IFERROR(INDEX(_ids!$A:$A,MATCH(B28&"|"&C28,_ids!$D:$D,0)),"MISSING") -> MISSING | B28: LAB20-AGG-02 | C28: 1/1/1 | D28: lag1 | K28: true | L28: To LAB20-F1-ACC-01 1/1/50
A29: =IFERROR(INDEX(_ids!$A:$A,MATCH(B29&"|"&C29,_ids!$D:$D,0)),"MISSING") -> MISSING | B29: LAB20-F1-ACC-01 | C29: 1/1/50 | D29: lag1 | K29: true | L29: To LAB20-AGG-02 1/1/1
A30: =IFERROR(INDEX(_ids!$A:$A,MATCH(B30&"|"&C30,_ids!$D:$D,0)),"MISSING") -> MISSING | B30: LAB20-AGG-01 | C30: 1/1/2 | D30: lag2 | K30: true | L30: To LAB20-F1-ACC-02 1/1/49
A31: =IFERROR(INDEX(_ids!$A:$A,MATCH(B31&"|"&C31,_ids!$D:$D,0)),"MISSING") -> MISSING | B31: LAB20-F1-ACC-02 | C31: 1/1/49 | D31: lag1 | K31: true | L31: To LAB20-AGG-01 1/1/2
A32: =IFERROR(INDEX(_ids!$A:$A,MATCH(B32&"|"&C32,_ids!$D:$D,0)),"MISSING") -> MISSING | B32: LAB20-AGG-02 | C32: 1/1/2 | D32: lag2 | K32: true | L32: To LAB20-F1-ACC-02 1/1/50
A33: =IFERROR(INDEX(_ids!$A:$A,MATCH(B33&"|"&C33,_ids!$D:$D,0)),"MISSING") -> MISSING | B33: LAB20-F1-ACC-02 | C33: 1/1/50 | D33: lag1 | K33: true | L33: To LAB20-AGG-02 1/1/2
A34: =IFERROR(INDEX(_ids!$A:$A,MATCH(B34&"|"&C34,_ids!$D:$D,0)),"MISSING") -> MISSING | B34: LAB20-AGG-01 | C34: 1/1/3 | D34: lag3 | K34: true | L34: To LAB20-F1-ACC-03 1/1/49
A35: =IFERROR(INDEX(_ids!$A:$A,MATCH(B35&"|"&C35,_ids!$D:$D,0)),"MISSING") -> MISSING | B35: LAB20-F1-ACC-03 | C35: 1/1/49 | D35: lag1 | K35: true | L35: To LAB20-AGG-01 1/1/3
A36: =IFERROR(INDEX(_ids!$A:$A,MATCH(B36&"|"&C36,_ids!$D:$D,0)),"MISSING") -> MISSING | B36: LAB20-AGG-02 | C36: 1/1/3 | D36: lag3 | K36: true | L36: To LAB20-F1-ACC-03 1/1/50
A37: =IFERROR(INDEX(_ids!$A:$A,MATCH(B37&"|"&C37,_ids!$D:$D,0)),"MISSING") -> MISSING | B37: LAB20-F1-ACC-03 | C37: 1/1/50 | D37: lag1 | K37: true | L37: To LAB20-AGG-02 1/1/3
... A65: =IFERROR(INDEX(_ids!$A:$A,MATCH(B65&"|"&C65,_ids!$D:$D,0)),"MISSING") -> MISSING | B65: LAB20-F2-ACC-05 | C65: 1/1/50 | D65: lag1 | K65: true | L65: To LAB20-AGG-02 1/1/10
A66: =IFERROR(INDEX(_ids!$A:$A,MATCH(B66&"|"&C66,_ids!$D:$D,0)),"MISSING") -> MISSING | B66: LAB20-F1-ACC-01 | C66: 1/1/1 | E66: tagged | F66: LAB20 VLANs | G66: 10 | H66: 20 | K66: true | L66: USER
A67: =IFERROR(INDEX(_ids!$A:$A,MATCH(B67&"|"&C67,_ids!$D:$D,0)),"MISSING") -> MISSING | B67: LAB20-F1-ACC-01 | C67: 1/1/2 | E67: tagged | F67: LAB20 VLANs | G67: 10 | H67: 20 | K67: true | L67: USER
...

Sheet _ids
A1: ID | B1: Device | C1: Name | D1: key (formula, do not edit) | F1: Paste the interface export here (columns A-C: ID, Device, Name). Column D fills itself; 08_ports_update reads the IDs from it.
D2: =IF(A2="","",B2&"|"&C2)
D3: =IF(A3="","",B3&"|"&C3)
D4: =IF(A4="","",B4&"|"&C4)
D5: =IF(A5="","",B5&"|"&C5)
D6: =IF(A6="","",B6&"|"&C6)
D7: =IF(A7="","",B7&"|"&C7)
D8: =IF(A8="","",B8&"|"&C8)
D9: =IF(A9="","",B9&"|"&C9)
D10: =IF(A10="","",B10&"|"&C10)
D11: =IF(A11="","",B11&"|"&C11)
D12: =IF(A12="","",B12&"|"&C12)
D13: =IF(A13="","",B13&"|"&C13)
... D1501: =IF(A1501="","",B1501&"|"&C1501)

Sheet 09_cables
A1: side_a_device | B1: side_a_type | C1: side_a_name | D1: side_b_device | E1: side_b_type | F1: side_b_name | G1: type | H1: status | I1: label
A2: LAB20-CORE-01 | B2: dcim.interface | C2: 1/1/53 | D2: LAB20-CORE-02 | E2: dcim.interface | F2: 1/1/53 | G2: dac-passive | H2: connected | I2: VSX ISL
A3: LAB20-CORE-01 | B3: dcim.interface | C3: 1/1/54 | D3: LAB20-CORE-02 | E3: dcim.interface | F3: 1/1/54 | G3: dac-passive | H3: connected | I3: VSX ISL
A4: LAB20-CORE-01 | B4: dcim.interface | C4: 1/1/48 | D4: LAB20-CORE-02 | E4: dcim.interface | F4: 1/1/48 | G4: dac-passive | H4: connected | I4: VSX keepalive
A5: LAB20-AGG-01 | B5: dcim.interface | C5: 1/1/53 | D5: LAB20-AGG-02 | E5: dcim.interface | F5: 1/1/53 | G5: dac-passive | H5: connected | I5: VSX ISL
A6: LAB20-AGG-01 | B6: dcim.interface | C6: 1/1/54 | D6: LAB20-AGG-02 | E6: dcim.interface | F6: 1/1/54 | G6: dac-passive | H6: connected | I6: VSX ISL
A7: LAB20-AGG-01 | B7: dcim.interface | C7: 1/1/48 | D7: LAB20-AGG-02 | E7: dcim.interface | F7: 1/1/48 | G7: dac-passive | H7: connected | I7: VSX keepalive
A8: LAB20-CORE-01 | B8: dcim.interface | C8: 1/1/49 | D8: LAB20-AGG-01 | E8: dcim.interface | F8: 1/1/49 | G8: smf | H8: connected | I8: core-agg
A9: LAB20-CORE-01 | B9: dcim.interface | C9: 1/1/50 | D9: LAB20-AGG-02 | E9: dcim.interface | F9: 1/1/49 | G9: smf | H9: connected | I9: core-agg
A10: LAB20-CORE-02 | B10: dcim.interface | C10: 1/1/49 | D10: LAB20-AGG-01 | E10: dcim.interface | F10: 1/1/50 | G10: smf | H10: connected | I10: core-agg
A11: LAB20-CORE-02 | B11: dcim.interface | C11: 1/1/50 | D11: LAB20-AGG-02 | E11: dcim.interface | F11: 1/1/50 | G11: smf | H11: connected | I11: core-agg
A12: LAB20-F1-ACC-01 | B12: dcim.interface | C12: 1/1/49 | D12: LAB20-AGG-01 | E12: dcim.interface | F12: 1/1/1 | G12: mmf-om4 | H12: connected | I12: access uplink
... A31: LAB20-F2-ACC-05 | B31: dcim.interface | C31: 1/1/50 | D31: LAB20-AGG-02 | E31: dcim.interface | F31: 1/1/10 | G31: mmf-om4 | H31: connected | I31: access uplink

Sheet 10_ip_addresses
A1: address | B1: vrf | C1: status | D1: role | E1: device | F1: interface | G1: is_primary | H1: description
A2: 10.20.253.11/24 | B2: mgmt | C2: active | E2: LAB20-CORE-01 | F2: mgmt | G2: true | H2: OOB management
A3: 10.20.254.1/32 | C3: active | E3: LAB20-CORE-01 | F3: loopback0 | G3: false | H3: Router ID
A4: 10.20.253.12/24 | B4: mgmt | C4: active | E4: LAB20-CORE-02 | F4: mgmt | G4: true | H4: OOB management
A5: 10.20.254.2/32 | C5: active | E5: LAB20-CORE-02 | F5: loopback0 | G5: false | H5: Router ID
A6: 10.20.253.21/24 | B6: mgmt | C6: active | E6: LAB20-AGG-01 | F6: mgmt | G6: true | H6: OOB management
A7: 10.20.254.11/32 | C7: active | E7: LAB20-AGG-01 | F7: loopback0 | G7: false | H7: Router ID
A8: 10.20.253.22/24 | B8: mgmt | C8: active | E8: LAB20-AGG-02 | F8: mgmt | G8: true | H8: OOB management
A9: 10.20.254.12/32 | C9: active | E9: LAB20-AGG-02 | F9: loopback0 | G9: false | H9: Router ID
A10: 10.20.252.0/31 | B10: KA | C10: active | E10: LAB20-CORE-01 | F10: 1/1/48 | G10: false | H10: VSX keepalive
A11: 10.20.252.1/31 | B11: KA | C11: active | E11: LAB20-CORE-02 | F11: 1/1/48 | G11: false | H11: VSX keepalive
A12: 10.20.252.2/31 | B12: KA | C12: active | E12: LAB20-AGG-01 | F12: 1/1/48 | G12: false | H12: VSX keepalive
A13: 10.20.252.3/31 | B13: KA | C13: active | E13: LAB20-AGG-02 | F13: 1/1/48 | G13: false | H13: VSX keepalive
A14: 10.20.251.0/31 | C14: active | E14: LAB20-CORE-01 | F14: 1/1/49 | G14: false | H14: P2P to LAB20-AGG-01
A15: 10.20.251.1/31 | C15: active | E15: LAB20-AGG-01 | F15: 1/1/49 | G15: false | H15: P2P to LAB20-CORE-01
A16: 10.20.251.2/31 | C16: active | E16: LAB20-CORE-01 | F16: 1/1/50 | G16: false | H16: P2P to LAB20-AGG-02
A17: 10.20.251.3/31 | C17: active | E17: LAB20-AGG-02 | F17: 1/1/49 | G17: false | H17: P2P to LAB20-CORE-01
A18: 10.20.251.4/31 | C18: active | E18: LAB20-CORE-02 | F18: 1/1/49 | G18: false | H18: P2P to LAB20-AGG-01
A19: 10.20.251.5/31 | C19: active | E19: LAB20-AGG-01 | F19: 1/1/50 | G19: false | H19: P2P to LAB20-CORE-02
A20: 10.20.251.6/31 | C20: active | E20: LAB20-CORE-02 | F20: 1/1/50 | G20: false | H20: P2P to LAB20-AGG-02
A21: 10.20.251.7/31 | C21: active | E21: LAB20-AGG-02 | F21: 1/1/50 | G21: false | H21: P2P to LAB20-CORE-02
A22: 10.20.10.2/24 | C22: active | E22: LAB20-AGG-01 | F22: vlan10 | G22: false | H22: Users
A23: 10.20.10.1/24 | C23: active | D23: vip | E23: LAB20-AGG-01 | F23: vlan10 | G23: false | H23: Users gateway (VSX active-gateway)
A24: 10.20.10.3/24 | C24: active | E24: LAB20-AGG-02 | F24: vlan10 | G24: false | H24: Users
A25: 10.20.10.1/24 | C25: active | D25: vip | E25: LAB20-AGG-02 | F25: vlan10 | G25: false | H25: Users gateway (VSX active-gateway)
A26: 10.20.20.2/24 | C26: active | E26: LAB20-AGG-01 | F26: vlan20 | G26: false | H26: Voice
A27: 10.20.20.1/24 | C27: active | D27: vip | E27: LAB20-AGG-01 | F27: vlan20 | G27: false | H27: Voice gateway (VSX active-gateway)
A28: 10.20.20.3/24 | C28: active | E28: LAB20-AGG-02 | F28: vlan20 | G28: false | H28: Voice
A29: 10.20.20.1/24 | C29: active | D29: vip | E29: LAB20-AGG-02 | F29: vlan20 | G29: false | H29: Voice gateway (VSX active-gateway)
A30: 10.20.30.2/24 | C30: active | E30: LAB20-AGG-01 | F30: vlan30 | G30: false | H30: WiFi
A31: 10.20.30.1/24 | C31: active | D31: vip | E31: LAB20-AGG-01 | F31: vlan30 | G31: false | H31: WiFi gateway (VSX active-gateway)
A32: 10.20.30.3/24 | C32: active | E32: LAB20-AGG-02 | F32: vlan30 | G32: false | H32: WiFi
A33: 10.20.30.1/24 | C33: active | D33: vip | E33: LAB20-AGG-02 | F33: vlan30 | G33: false | H33: WiFi gateway (VSX active-gateway)
A34: 10.20.99.2/24 | C34: active | E34: LAB20-AGG-01 | F34: vlan99 | G34: false | H34: Mgmt
A35: 10.20.99.1/24 | C35: active | D35: vip | E35: LAB20-AGG-01 | F35: vlan99 | G35: false | H35: Mgmt gateway (VSX active-gateway)
A36: 10.20.99.3/24 | C36: active | E36: LAB20-AGG-02 | F36: vlan99 | G36: false | H36: Mgmt
A37: 10.20.99.1/24 | C37: active | D37: vip | E37: LAB20-AGG-02 | F37: vlan99 | G37: false | H37: Mgmt gateway (VSX active-gateway)
A38: 10.20.99.101/24 | C38: active | E38: LAB20-F1-ACC-01 | F38: vlan99 | G38: true | H38: Management
A39: 10.20.99.102/24 | C39: active | E39: LAB20-F1-ACC-02 | F39: vlan99 | G39: true | H39: Management
A40: 10.20.99.103/24 | C40: active | E40: LAB20-F1-ACC-03 | F40: vlan99 | G40: true | H40: Management
...

Sheet 11_context_GUI
A1: Where | B1: Object | C1: JSON to paste
A2: Customization > Config Contexts > Add (Name, Weight 1000, Sites = LAB20, Data) | B2: standards-lab20 | C2: {"dns_servers": ["10.20.30.53"], "ntp_servers": ["10.20.30.123"], "syslog_servers": ["10.20.30.60"], "dhcp_servers": ["10.20.30.67"], "tacacs_servers": ["10.20.30.49"], "snmp": {"v3_user": "netmon", "location_prefix": "LAB20"}, "ospf": {"process": 1, "area": "0.0.0.0"}, "spanning_tree": {"mode": "mstp", "config_name": "LAB20", "config_revision": 1}, "active_gateway_mac": "12:00:00:00:01:00", "access_mgmt_vlan": 99, "timezone": "europe/berlin", "banner": "Authorized access only. All activity is logged.\n"}
A3: Device > Edit > Local config context data | B3: LAB20-CORE-01 | C3: {"vsx": {"role": "primary", "system_mac": "02:00:20:00:00:01", "peer": "LAB20-CORE-02"}}
A4: Device > Edit > Local config context data | B4: LAB20-CORE-02 | C4: {"vsx": {"role": "secondary", "system_mac": "02:00:20:00:00:01", "peer": "LAB20-CORE-01"}}
A5: Device > Edit > Local config context data | B5: LAB20-AGG-01 | C5: {"vsx": {"role": "primary", "system_mac": "02:00:20:00:00:02", "peer": "LAB20-AGG-02"}}
A6: Device > Edit > Local config context data | B6: LAB20-AGG-02 | C6: {"vsx": {"role": "secondary", "system_mac": "02:00:20:00:00:02", "peer": "LAB20-AGG-01"}}
